[33mWARNING[0m:  [29-07-2024 15:08:47] chroma_server_nofile is set to 65535, but this is less than current soft limit of 1048575. chroma_server_nofile will not be set.
[32mINFO[0m:     [29-07-2024 15:08:48] Anonymized telemetry enabled. See                     https://docs.trychroma.com/telemetry for more information.
[36mDEBUG[0m:    [29-07-2024 15:08:48] Starting component System
[36mDEBUG[0m:    [29-07-2024 15:08:48] Starting component OpenTelemetryClient
[36mDEBUG[0m:    [29-07-2024 15:08:48] Starting component SqliteDB
[36mDEBUG[0m:    [29-07-2024 15:08:48] Starting component QuotaEnforcer
[36mDEBUG[0m:    [29-07-2024 15:08:48] Starting component Posthog
[36mDEBUG[0m:    [29-07-2024 15:08:48] Starting component LocalSegmentManager
[36mDEBUG[0m:    [29-07-2024 15:08:48] Starting component SegmentAPI
[32mINFO[0m:     [29-07-2024 15:08:48] Started server process [[36m16729[0m]
[32mINFO[0m:     [29-07-2024 15:08:48] Waiting for application startup.
[32mINFO[0m:     [29-07-2024 15:08:48] Application startup complete.
[32mINFO[0m:     [29-07-2024 15:08:48] Uvicorn running on [1mhttp://localhost:8000[0m (Press CTRL+C to quit)
[32mINFO[0m:     [29-07-2024 15:10:34] ::1:55148 - "GET /api/v1/tenants/default_tenant HTTP/1.1" 200
[32mINFO[0m:     [29-07-2024 15:10:34] ::1:55148 - "GET /api/v1/databases/default_database?tenant=default_tenant HTTP/1.1" 200
[32mINFO[0m:     [29-07-2024 15:10:34] ::1:55149 - "POST /api/v1/collections?tenant=default_tenant&database=default_database HTTP/1.1" 200
[32mINFO[0m:     [29-07-2024 15:38:23] ::1:56559 - "GET /api/v1/tenants/default_tenant HTTP/1.1" 200
[32mINFO[0m:     [29-07-2024 15:38:23] ::1:56559 - "GET /api/v1/databases/default_database?tenant=default_tenant HTTP/1.1" 200
[31mERROR[0m:    [29-07-2024 15:38:23] Collection sample_collection already exists
Traceback (most recent call last):
  File "/Library/Frameworks/Python.framework/Versions/3.11/lib/python3.11/site-packages/anyio/streams/memory.py", line 105, in receive
    return self.receive_nowait()
           ^^^^^^^^^^^^^^^^^^^^^
  File "/Library/Frameworks/Python.framework/Versions/3.11/lib/python3.11/site-packages/anyio/streams/memory.py", line 100, in receive_nowait
    raise WouldBlock
anyio.WouldBlock

During handling of the above exception, another exception occurred:

Traceback (most recent call last):
  File "/Library/Frameworks/Python.framework/Versions/3.11/lib/python3.11/site-packages/anyio/streams/memory.py", line 118, in receive
    return receiver.item
           ^^^^^^^^^^^^^
AttributeError: 'MemoryObjectItemReceiver' object has no attribute 'item'

During handling of the above exception, another exception occurred:

Traceback (most recent call last):
  File "/Library/Frameworks/Python.framework/Versions/3.11/lib/python3.11/site-packages/starlette/middleware/base.py", line 159, in call_next
    message = await recv_stream.receive()
              ^^^^^^^^^^^^^^^^^^^^^^^^^^^
  File "/Library/Frameworks/Python.framework/Versions/3.11/lib/python3.11/site-packages/anyio/streams/memory.py", line 120, in receive
    raise EndOfStream
anyio.EndOfStream

During handling of the above exception, another exception occurred:

Traceback (most recent call last):
  File "/Library/Frameworks/Python.framework/Versions/3.11/lib/python3.11/site-packages/chromadb/server/fastapi/__init__.py", line 76, in catch_exceptions_middleware
    return await call_next(request)
           ^^^^^^^^^^^^^^^^^^^^^^^^
  File "/Library/Frameworks/Python.framework/Versions/3.11/lib/python3.11/site-packages/starlette/middleware/base.py", line 165, in call_next
    raise app_exc
  File "/Library/Frameworks/Python.framework/Versions/3.11/lib/python3.11/site-packages/starlette/middleware/base.py", line 151, in coro
    await self.app(scope, receive_or_disconnect, send_no_error)
  File "/Library/Frameworks/Python.framework/Versions/3.11/lib/python3.11/site-packages/starlette/middleware/base.py", line 189, in __call__
    with collapse_excgroups():
  File "/Library/Frameworks/Python.framework/Versions/3.11/lib/python3.11/contextlib.py", line 155, in __exit__
    self.gen.throw(typ, value, traceback)
  File "/Library/Frameworks/Python.framework/Versions/3.11/lib/python3.11/site-packages/starlette/_utils.py", line 93, in collapse_excgroups
    raise exc
  File "/Library/Frameworks/Python.framework/Versions/3.11/lib/python3.11/site-packages/starlette/middleware/base.py", line 191, in __call__
    response = await self.dispatch_func(request, call_next)
               ^^^^^^^^^^^^^^^^^^^^^^^^^^^^^^^^^^^^^^^^^^^^
  File "/Library/Frameworks/Python.framework/Versions/3.11/lib/python3.11/site-packages/chromadb/server/fastapi/__init__.py", line 90, in check_http_version_middleware
    return await call_next(request)
           ^^^^^^^^^^^^^^^^^^^^^^^^
  File "/Library/Frameworks/Python.framework/Versions/3.11/lib/python3.11/site-packages/starlette/middleware/base.py", line 165, in call_next
    raise app_exc
  File "/Library/Frameworks/Python.framework/Versions/3.11/lib/python3.11/site-packages/starlette/middleware/base.py", line 151, in coro
    await self.app(scope, receive_or_disconnect, send_no_error)
  File "/Library/Frameworks/Python.framework/Versions/3.11/lib/python3.11/site-packages/starlette/middleware/exceptions.py", line 65, in __call__
    await wrap_app_handling_exceptions(self.app, conn)(scope, receive, send)
  File "/Library/Frameworks/Python.framework/Versions/3.11/lib/python3.11/site-packages/starlette/_exception_handler.py", line 64, in wrapped_app
    raise exc
  File "/Library/Frameworks/Python.framework/Versions/3.11/lib/python3.11/site-packages/starlette/_exception_handler.py", line 53, in wrapped_app
    await app(scope, receive, sender)
  File "/Library/Frameworks/Python.framework/Versions/3.11/lib/python3.11/site-packages/starlette/routing.py", line 756, in __call__
    await self.middleware_stack(scope, receive, send)
  File "/Library/Frameworks/Python.framework/Versions/3.11/lib/python3.11/site-packages/starlette/routing.py", line 776, in app
    await route.handle(scope, receive, send)
  File "/Library/Frameworks/Python.framework/Versions/3.11/lib/python3.11/site-packages/starlette/routing.py", line 297, in handle
    await self.app(scope, receive, send)
  File "/Library/Frameworks/Python.framework/Versions/3.11/lib/python3.11/site-packages/starlette/routing.py", line 77, in app
    await wrap_app_handling_exceptions(app, request)(scope, receive, send)
  File "/Library/Frameworks/Python.framework/Versions/3.11/lib/python3.11/site-packages/starlette/_exception_handler.py", line 64, in wrapped_app
    raise exc
  File "/Library/Frameworks/Python.framework/Versions/3.11/lib/python3.11/site-packages/starlette/_exception_handler.py", line 53, in wrapped_app
    await app(scope, receive, sender)
  File "/Library/Frameworks/Python.framework/Versions/3.11/lib/python3.11/site-packages/starlette/routing.py", line 72, in app
    response = await func(request)
               ^^^^^^^^^^^^^^^^^^^
  File "/Library/Frameworks/Python.framework/Versions/3.11/lib/python3.11/site-packages/fastapi/routing.py", line 278, in app
    raw_response = await run_endpoint_function(
                   ^^^^^^^^^^^^^^^^^^^^^^^^^^^^
  File "/Library/Frameworks/Python.framework/Versions/3.11/lib/python3.11/site-packages/fastapi/routing.py", line 191, in run_endpoint_function
    return await dependant.call(**values)
           ^^^^^^^^^^^^^^^^^^^^^^^^^^^^^^
  File "/Library/Frameworks/Python.framework/Versions/3.11/lib/python3.11/site-packages/chromadb/telemetry/opentelemetry/__init__.py", line 133, in async_wrapper
    return await f(*args, **kwargs)
           ^^^^^^^^^^^^^^^^^^^^^^^^
  File "/Library/Frameworks/Python.framework/Versions/3.11/lib/python3.11/site-packages/chromadb/server/fastapi/__init__.py", line 601, in create_collection
    await to_thread.run_sync(
  File "/Library/Frameworks/Python.framework/Versions/3.11/lib/python3.11/site-packages/anyio/to_thread.py", line 56, in run_sync
    return await get_async_backend().run_sync_in_worker_thread(
           ^^^^^^^^^^^^^^^^^^^^^^^^^^^^^^^^^^^^^^^^^^^^^^^^^^^^
  File "/Library/Frameworks/Python.framework/Versions/3.11/lib/python3.11/site-packages/anyio/_backends/_asyncio.py", line 2177, in run_sync_in_worker_thread
    return await future
           ^^^^^^^^^^^^
  File "/Library/Frameworks/Python.framework/Versions/3.11/lib/python3.11/site-packages/anyio/_backends/_asyncio.py", line 859, in run
    result = context.run(func, *args)
             ^^^^^^^^^^^^^^^^^^^^^^^^
  File "/Library/Frameworks/Python.framework/Versions/3.11/lib/python3.11/site-packages/chromadb/server/fastapi/__init__.py", line 590, in process_create_collection
    return self._api.create_collection(
           ^^^^^^^^^^^^^^^^^^^^^^^^^^^^
  File "/Library/Frameworks/Python.framework/Versions/3.11/lib/python3.11/site-packages/chromadb/telemetry/opentelemetry/__init__.py", line 146, in wrapper
    return f(*args, **kwargs)
           ^^^^^^^^^^^^^^^^^^
  File "/Library/Frameworks/Python.framework/Versions/3.11/lib/python3.11/site-packages/chromadb/api/segment.py", line 176, in create_collection
    coll, created = self._sysdb.create_collection(
                    ^^^^^^^^^^^^^^^^^^^^^^^^^^^^^^
  File "/Library/Frameworks/Python.framework/Versions/3.11/lib/python3.11/site-packages/chromadb/telemetry/opentelemetry/__init__.py", line 146, in wrapper
    return f(*args, **kwargs)
           ^^^^^^^^^^^^^^^^^^
  File "/Library/Frameworks/Python.framework/Versions/3.11/lib/python3.11/site-packages/chromadb/db/mixins/sysdb.py", line 229, in create_collection
    raise UniqueConstraintError(f"Collection {name} already exists")
chromadb.db.base.UniqueConstraintError: Collection sample_collection already exists
[32mINFO[0m:     [29-07-2024 15:38:23] ::1:56560 - "POST /api/v1/collections?tenant=default_tenant&database=default_database HTTP/1.1" 500
[32mINFO[0m:     [29-07-2024 15:39:09] ::1:56587 - "GET /api/v1/tenants/default_tenant HTTP/1.1" 200
[32mINFO[0m:     [29-07-2024 15:39:09] ::1:56587 - "GET /api/v1/databases/default_database?tenant=default_tenant HTTP/1.1" 200
[31mERROR[0m:    [29-07-2024 15:39:09] Collection sample_collection already exists
Traceback (most recent call last):
  File "/Library/Frameworks/Python.framework/Versions/3.11/lib/python3.11/site-packages/anyio/streams/memory.py", line 105, in receive
    return self.receive_nowait()
           ^^^^^^^^^^^^^^^^^^^^^
  File "/Library/Frameworks/Python.framework/Versions/3.11/lib/python3.11/site-packages/anyio/streams/memory.py", line 100, in receive_nowait
    raise WouldBlock
anyio.WouldBlock

During handling of the above exception, another exception occurred:

Traceback (most recent call last):
  File "/Library/Frameworks/Python.framework/Versions/3.11/lib/python3.11/site-packages/anyio/streams/memory.py", line 118, in receive
    return receiver.item
           ^^^^^^^^^^^^^
AttributeError: 'MemoryObjectItemReceiver' object has no attribute 'item'

During handling of the above exception, another exception occurred:

Traceback (most recent call last):
  File "/Library/Frameworks/Python.framework/Versions/3.11/lib/python3.11/site-packages/starlette/middleware/base.py", line 159, in call_next
    message = await recv_stream.receive()
              ^^^^^^^^^^^^^^^^^^^^^^^^^^^
  File "/Library/Frameworks/Python.framework/Versions/3.11/lib/python3.11/site-packages/anyio/streams/memory.py", line 120, in receive
    raise EndOfStream
anyio.EndOfStream

During handling of the above exception, another exception occurred:

Traceback (most recent call last):
  File "/Library/Frameworks/Python.framework/Versions/3.11/lib/python3.11/site-packages/chromadb/server/fastapi/__init__.py", line 76, in catch_exceptions_middleware
    return await call_next(request)
           ^^^^^^^^^^^^^^^^^^^^^^^^
  File "/Library/Frameworks/Python.framework/Versions/3.11/lib/python3.11/site-packages/starlette/middleware/base.py", line 165, in call_next
    raise app_exc
  File "/Library/Frameworks/Python.framework/Versions/3.11/lib/python3.11/site-packages/starlette/middleware/base.py", line 151, in coro
    await self.app(scope, receive_or_disconnect, send_no_error)
  File "/Library/Frameworks/Python.framework/Versions/3.11/lib/python3.11/site-packages/starlette/middleware/base.py", line 189, in __call__
    with collapse_excgroups():
  File "/Library/Frameworks/Python.framework/Versions/3.11/lib/python3.11/contextlib.py", line 155, in __exit__
    self.gen.throw(typ, value, traceback)
  File "/Library/Frameworks/Python.framework/Versions/3.11/lib/python3.11/site-packages/starlette/_utils.py", line 93, in collapse_excgroups
    raise exc
  File "/Library/Frameworks/Python.framework/Versions/3.11/lib/python3.11/site-packages/starlette/middleware/base.py", line 191, in __call__
    response = await self.dispatch_func(request, call_next)
               ^^^^^^^^^^^^^^^^^^^^^^^^^^^^^^^^^^^^^^^^^^^^
  File "/Library/Frameworks/Python.framework/Versions/3.11/lib/python3.11/site-packages/chromadb/server/fastapi/__init__.py", line 90, in check_http_version_middleware
    return await call_next(request)
           ^^^^^^^^^^^^^^^^^^^^^^^^
  File "/Library/Frameworks/Python.framework/Versions/3.11/lib/python3.11/site-packages/starlette/middleware/base.py", line 165, in call_next
    raise app_exc
  File "/Library/Frameworks/Python.framework/Versions/3.11/lib/python3.11/site-packages/starlette/middleware/base.py", line 151, in coro
    await self.app(scope, receive_or_disconnect, send_no_error)
  File "/Library/Frameworks/Python.framework/Versions/3.11/lib/python3.11/site-packages/starlette/middleware/exceptions.py", line 65, in __call__
    await wrap_app_handling_exceptions(self.app, conn)(scope, receive, send)
  File "/Library/Frameworks/Python.framework/Versions/3.11/lib/python3.11/site-packages/starlette/_exception_handler.py", line 64, in wrapped_app
    raise exc
  File "/Library/Frameworks/Python.framework/Versions/3.11/lib/python3.11/site-packages/starlette/_exception_handler.py", line 53, in wrapped_app
    await app(scope, receive, sender)
  File "/Library/Frameworks/Python.framework/Versions/3.11/lib/python3.11/site-packages/starlette/routing.py", line 756, in __call__
    await self.middleware_stack(scope, receive, send)
  File "/Library/Frameworks/Python.framework/Versions/3.11/lib/python3.11/site-packages/starlette/routing.py", line 776, in app
    await route.handle(scope, receive, send)
  File "/Library/Frameworks/Python.framework/Versions/3.11/lib/python3.11/site-packages/starlette/routing.py", line 297, in handle
    await self.app(scope, receive, send)
  File "/Library/Frameworks/Python.framework/Versions/3.11/lib/python3.11/site-packages/starlette/routing.py", line 77, in app
    await wrap_app_handling_exceptions(app, request)(scope, receive, send)
  File "/Library/Frameworks/Python.framework/Versions/3.11/lib/python3.11/site-packages/starlette/_exception_handler.py", line 64, in wrapped_app
    raise exc
  File "/Library/Frameworks/Python.framework/Versions/3.11/lib/python3.11/site-packages/starlette/_exception_handler.py", line 53, in wrapped_app
    await app(scope, receive, sender)
  File "/Library/Frameworks/Python.framework/Versions/3.11/lib/python3.11/site-packages/starlette/routing.py", line 72, in app
    response = await func(request)
               ^^^^^^^^^^^^^^^^^^^
  File "/Library/Frameworks/Python.framework/Versions/3.11/lib/python3.11/site-packages/fastapi/routing.py", line 278, in app
    raw_response = await run_endpoint_function(
                   ^^^^^^^^^^^^^^^^^^^^^^^^^^^^
  File "/Library/Frameworks/Python.framework/Versions/3.11/lib/python3.11/site-packages/fastapi/routing.py", line 191, in run_endpoint_function
    return await dependant.call(**values)
           ^^^^^^^^^^^^^^^^^^^^^^^^^^^^^^
  File "/Library/Frameworks/Python.framework/Versions/3.11/lib/python3.11/site-packages/chromadb/telemetry/opentelemetry/__init__.py", line 133, in async_wrapper
    return await f(*args, **kwargs)
           ^^^^^^^^^^^^^^^^^^^^^^^^
  File "/Library/Frameworks/Python.framework/Versions/3.11/lib/python3.11/site-packages/chromadb/server/fastapi/__init__.py", line 601, in create_collection
    await to_thread.run_sync(
  File "/Library/Frameworks/Python.framework/Versions/3.11/lib/python3.11/site-packages/anyio/to_thread.py", line 56, in run_sync
    return await get_async_backend().run_sync_in_worker_thread(
           ^^^^^^^^^^^^^^^^^^^^^^^^^^^^^^^^^^^^^^^^^^^^^^^^^^^^
  File "/Library/Frameworks/Python.framework/Versions/3.11/lib/python3.11/site-packages/anyio/_backends/_asyncio.py", line 2177, in run_sync_in_worker_thread
    return await future
           ^^^^^^^^^^^^
  File "/Library/Frameworks/Python.framework/Versions/3.11/lib/python3.11/site-packages/anyio/_backends/_asyncio.py", line 859, in run
    result = context.run(func, *args)
             ^^^^^^^^^^^^^^^^^^^^^^^^
  File "/Library/Frameworks/Python.framework/Versions/3.11/lib/python3.11/site-packages/chromadb/server/fastapi/__init__.py", line 590, in process_create_collection
    return self._api.create_collection(
           ^^^^^^^^^^^^^^^^^^^^^^^^^^^^
  File "/Library/Frameworks/Python.framework/Versions/3.11/lib/python3.11/site-packages/chromadb/telemetry/opentelemetry/__init__.py", line 146, in wrapper
    return f(*args, **kwargs)
           ^^^^^^^^^^^^^^^^^^
  File "/Library/Frameworks/Python.framework/Versions/3.11/lib/python3.11/site-packages/chromadb/api/segment.py", line 176, in create_collection
    coll, created = self._sysdb.create_collection(
                    ^^^^^^^^^^^^^^^^^^^^^^^^^^^^^^
  File "/Library/Frameworks/Python.framework/Versions/3.11/lib/python3.11/site-packages/chromadb/telemetry/opentelemetry/__init__.py", line 146, in wrapper
    return f(*args, **kwargs)
           ^^^^^^^^^^^^^^^^^^
  File "/Library/Frameworks/Python.framework/Versions/3.11/lib/python3.11/site-packages/chromadb/db/mixins/sysdb.py", line 229, in create_collection
    raise UniqueConstraintError(f"Collection {name} already exists")
chromadb.db.base.UniqueConstraintError: Collection sample_collection already exists
[32mINFO[0m:     [29-07-2024 15:39:09] ::1:56588 - "POST /api/v1/collections?tenant=default_tenant&database=default_database HTTP/1.1" 500
[32mINFO[0m:     [30-07-2024 19:51:08] Shutting down
[32mINFO[0m:     [30-07-2024 19:51:08] Waiting for application shutdown.
[36mDEBUG[0m:    [30-07-2024 19:51:08] Stopping component System
[36mDEBUG[0m:    [30-07-2024 19:51:08] Stopping component SegmentAPI
[36mDEBUG[0m:    [30-07-2024 19:51:08] Stopping component LocalSegmentManager
[36mDEBUG[0m:    [30-07-2024 19:51:08] Stopping component Posthog
[36mDEBUG[0m:    [30-07-2024 19:51:08] Stopping component QuotaEnforcer
[36mDEBUG[0m:    [30-07-2024 19:51:08] Stopping component SqliteDB
[36mDEBUG[0m:    [30-07-2024 19:51:08] Stopping component OpenTelemetryClient
[32mINFO[0m:     [30-07-2024 19:51:08] Application shutdown complete.
[32mINFO[0m:     [30-07-2024 19:51:08] Finished server process [[36m16729[0m]
[33mWARNING[0m:  [30-07-2024 19:51:16] chroma_server_nofile is set to 65535, but this is less than current soft limit of 1048575. chroma_server_nofile will not be set.
[32mINFO[0m:     [30-07-2024 19:51:17] Anonymized telemetry enabled. See                     https://docs.trychroma.com/telemetry for more information.
[36mDEBUG[0m:    [30-07-2024 19:51:17] Starting component System
[36mDEBUG[0m:    [30-07-2024 19:51:17] Starting component OpenTelemetryClient
[36mDEBUG[0m:    [30-07-2024 19:51:17] Starting component SqliteDB
[36mDEBUG[0m:    [30-07-2024 19:51:17] Starting component QuotaEnforcer
[36mDEBUG[0m:    [30-07-2024 19:51:17] Starting component Posthog
[36mDEBUG[0m:    [30-07-2024 19:51:17] Starting component LocalSegmentManager
[36mDEBUG[0m:    [30-07-2024 19:51:17] Starting component SegmentAPI
[32mINFO[0m:     [30-07-2024 19:51:17] Started server process [[36m58079[0m]
[32mINFO[0m:     [30-07-2024 19:51:17] Waiting for application startup.
[32mINFO[0m:     [30-07-2024 19:51:17] Application startup complete.
[32mINFO[0m:     [30-07-2024 19:51:17] Uvicorn running on [1mhttp://localhost:8000[0m (Press CTRL+C to quit)
